Workbook

Sheet Applications
A1: Company | B1: Role | C1: Application Link | D1: 5 JPMC Bullets (final version) | E1: Final Avg (/10) | F1: Baseline Avg (/10) | G1: Eligibility / Fit Note | H1: Bullet source
A2: Amazon (Twitch) | B2: Software Engineer I (Seattle) | C2: https://www.amazon.jobs/en/jobs/3141336/software-engineer-i | D2: • Own 4 Java/Spring Boot services in JPMC's payment-authorization platform on AWS (38M transactions/day, 99.95% availability); led the zero-downtime Java 17 upgrade. • Cut p99 latency of the settlement-status API from 620ms to 210ms by adding a Redis cache and rewriting 3 slow Oracle queries. • Built CI/CD with automated integration tests, moving releases from bi-weekly to on-demand and cutting rollbacks from 12% to 3%. • On-call for 4 services; Grafana/Splunk alerts and runbooks cut mean-time-to-detect from 25 to 6 minutes and halved repeat pages. • Lifted unit-test coverage on owned services from 52% to 81% in 3 weeks, using Copilot/Claude Code to draft tests I reviewed by hand. | E2: =AVERAGEIFS('Validation (Final)'!$L$2:$L$281,'Validation (Final)'!$A$2:$A$281,A2,'Validation (Final)'!$B$2:$B$281,B2) -> 7.6 | F2: =AVERAGEIFS('Validation (Final)'!$M$2:$M$281,'Validation (Final)'!$A$2:$A$281,A2,'Validation (Final)'!$B$2:$B$281,B2) -> 7.37 | G2: Asks ~1+ yr professional experience; good YOE match. | H2: Original 14 (full revision history)
A3: Amazon | B3: Software Engineer I, Payments | C3: https://www.amazon.jobs/en/jobs/10502486/software-engineer-i-payments | D3: • Shipped 6 features to a $1.2B/day payment platform via 10%-to-100% staged rollouts and feature flags, with zero Sev-1 incidents. • Fixed a duplicate-posting bug class by designing idempotency keys for settlement retries, eliminating ~120 duplicate transactions/month. • Migrated 9 nightly batch jobs to Kafka event-driven services, cutting end-to-end settlement processing from 4 hours to 25 minutes. • Added reconciliation checks and audit logging that caught 14 ledger mismatches before customers saw them. • Built an LLM script to triage failed-payment tickets (87% accuracy on 300 labeled tickets), saving the team ~6 hrs/week. | E3: =AVERAGEIFS('Validation (Final)'!$L$2:$L$281,'Validation (Final)'!$A$2:$A$281,A3,'Validation (Final)'!$B$2:$B$281,B3) -> 7.77 | F3: =AVERAGEIFS('Validation (Final)'!$M$2:$M$281,'Validation (Final)'!$A$2:$A$281,A3,'Validation (Final)'!$B$2:$B$281,B3) -> 7.43 | G3: SDE I band; ~0-2 yrs fits. Payments domain overlaps with JPMC. | H3: Original 14 (full revision history)
A4: Mastercard | B4: Software Engineer I (O'Fallon, MO) | C4: https://careers.mastercard.com/us/en/job/R-292618/Software-Engineer-I | D4: • Maintain 4 Java services in a 38M-events/day transaction pipeline at 99.95% availability, including on-call. • Containerized 4 services and automated tests in CI, cutting build-and-deploy from 45 to 12 minutes and saving the team ~15 engineer-hours/month. • Remediated 23 OWASP-class findings (injection, auth gaps) across 4 services before the audit deadline, fixing the 5 critical ones within 48 hours. • Cut month-end reporting queries from 90s to 8s with materialized views, unblocking close for 40 ops users. • Wrote an onboarding guide and setup scripts for a 12-person team, getting new hires to a first merged PR in 2 weeks instead of 5. | E4: =AVERAGEIFS('Validation (Final)'!$L$2:$L$281,'Validation (Final)'!$A$2:$A$281,A4,'Validation (Final)'!$B$2:$B$281,B4) -> 7.37 | F4: =AVERAGEIFS('Validation (Final)'!$M$2:$M$281,'Validation (Final)'!$A$2:$A$281,A4,'Validation (Final)'!$B$2:$B$281,B4) -> 6.53 | G4: Entry-level band; you're at/above level. | H4: Original 14 (full revision history)
A5: Addepar | B5: Software Engineer, Full Stack - Alts & Data Management | C5: https://job-boards.greenhouse.io/addepar1/jobs/8538666002 | D5: • Built full-stack features (React/TypeScript + Java APIs) for a 60-user internal ops dashboard used to monitor settlement exceptions. • Designed a pipeline normalizing 5 upstream data feeds into one schema, eliminating ~10 hrs/week of manual reconciliation. • Cut dashboard load time from 8s to 1.5s via query optimization and pagination over 20M-row tables. • Wrote 140 integration and data-validation tests that stopped 14 bad-data incidents from reaching client-facing reports. • Prototyped natural-language querying over exception data with an LLM, measured at 87% accuracy on a 300-case eval set. | E5: =AVERAGEIFS('Validation (Final)'!$L$2:$L$281,'Validation (Final)'!$A$2:$A$281,A5,'Validation (Final)'!$B$2:$B$281,B5) -> 7.74 | F5: =AVERAGEIFS('Validation (Final)'!$M$2:$M$281,'Validation (Final)'!$A$2:$A$281,A5,'Validation (Final)'!$B$2:$B$281,B5) -> 7.7 | G5: Requires 2+ yrs full stack OR 1+ yr each FE/BE; borderline, stress both layers. | H5: Original 14 (full revision history)
A6: Addepar | B6: Software Engineer, Fullstack | C6: https://job-boards.greenhouse.io/addepar1/jobs/8606946002 | D6: • Shipped 6 features end-to-end (React, REST, Oracle) for the exceptions dashboard, lifting weekly active use from 55% to 85%. • Refactored the settlement-status module behind a clean interface, deleting ~2K duplicated lines and halving feature lead time (2 weeks to 1) with zero regressions across 300 tests. • Introduced OpenAPI contracts across 3 frontend/backend teams and generated typed clients, cutting integration bugs 40%. • Owned the settlement-exceptions dashboard from design doc to production, using feature flags and monitoring for a zero-downtime rollout to 60 users. • Wrote an AI-assisted dev playbook for 8 teammates; PR cycle time fell from 3 days to 1.8 with review standards unchanged. | E6: =AVERAGEIFS('Validation (Final)'!$L$2:$L$281,'Validation (Final)'!$A$2:$A$281,A6,'Validation (Final)'!$B$2:$B$281,B6) -> 7.44 | F6: =AVERAGEIFS('Validation (Final)'!$M$2:$M$281,'Validation (Final)'!$A$2:$A$281,A6,'Validation (Final)'!$B$2:$B$281,B6) -> 6.8 | G6: Check posting for exact YOE bar before applying. | H6: Original 14 (full revision history)
A7: Rescale | B7: Software Engineer, Full Stack - AI & Data | C7: https://jobs.ashbyhq.com/rescale/fdba3410-d255-4879-9a6e-bed488b4a1fc | D7: • Built distributed Java services on AWS (ECS, SQS) handling 38M events/day; autoscaling cut compute cost 22%. • Designed async retry + dead-letter handling that raised job success rate from 96.8% to 99.7%. • Built Grafana/Splunk alerting that cut mean-time-to-detect from 25 to 6 minutes across 4 distributed services. • Built an LLM triage assistant that classifies failed jobs and proposes fixes; engineers accepted its suggestion in ~35% of cases during a 4-week pilot. • Packaged our AWS setup as Terraform modules adopted by 3 teams: environment setup fell from 2 days to 2 hours and config drift disappeared. | E7: =AVERAGEIFS('Validation (Final)'!$L$2:$L$281,'Validation (Final)'!$A$2:$A$281,A7,'Validation (Final)'!$B$2:$B$281,B7) -> 7.69 | F7: =AVERAGEIFS('Validation (Final)'!$M$2:$M$281,'Validation (Final)'!$A$2:$A$281,A7,'Validation (Final)'!$B$2:$B$281,B7) -> 7.15 | G7: Posting cites 1-3 yrs backend/distributed systems on a major cloud + LLM/agent exposure. | H7: Original 14 (full revision history)
A8: Affirm | B8: Software Engineer, Early Career (NYC) | C8: https://job-boards.greenhouse.io/affirm/jobs/8008649003 | D8: • Kept 4 Java/Kafka services at 99.95% availability through 2 peak-volume spikes by pre-scaling consumers and load-testing at 2x. • Added validation rules that cut erroneous postings 60% with false rejects under 0.5%. • Raised service availability from 99.5% to 99.95% via circuit breakers, retries, and load testing at 2x peak. • Automated routine exception handling (retries, re-queues), freeing ~10 engineer-hours/week and cutting exception-resolution time from 20 to 7 minutes. • Used LLMs to generate test fixtures and summarize incidents, halving postmortem prep (4 hours to 2) with every output hand-reviewed. | E8: =AVERAGEIFS('Validation (Final)'!$L$2:$L$281,'Validation (Final)'!$A$2:$A$281,A8,'Validation (Final)'!$B$2:$B$281,B8) -> 7.59 | F8: =AVERAGEIFS('Validation (Final)'!$M$2:$M$281,'Validation (Final)'!$A$2:$A$281,A8,'Validation (Final)'!$B$2:$B$281,B8) -> 6.85 | G8: Older Greenhouse ID; confirm it's still open. | H8: Original 14 (full revision history)
A9: Palantir | B9: Forward Deployed Software Engineer, New Grad - Commercial | C9: https://jobs.lever.co/palantir/e500bcf3-19d8-4d3c-b340-4d76e4a55b40 | D9: • Embedded with ops stakeholders to scope and ship a settlement-exceptions tool adopted by 60 users in 4 weeks. • Consolidated 5 data sources into one dashboard, replacing a ~10 hr/week manual reporting process. • Turned a vague ops request into a scoped tool in 1 week by interviewing 6 analysts; shipped an MVP next sprint, now used daily by 60. • Traced recurring data-mismatch tickets across 3 systems to a timezone bug in one feed; the fix cut related tickets 40%. • Prototyped an LLM workflow for ticket triage with human-in-loop review, reaching 87% accuracy. | E9: =AVERAGEIFS('Validation (Final)'!$L$2:$L$281,'Validation (Final)'!$A$2:$A$281,A9,'Validation (Final)'!$B$2:$B$281,B9) -> 7.83 | F9: =AVERAGEIFS('Validation (Final)'!$M$2:$M$281,'Validation (Final)'!$A$2:$A$281,A9,'Validation (Final)'!$B$2:$B$281,B9) -> 7.24 | G9: New-grad track; may require recent-grad status. | H9: Original 14 (full revision history)
A10: Harvey | B10: Software Engineer, New Grad (2027) | C10: https://jobs.ashbyhq.com/harvey/4d8dc9ba-eb86-4d88-af7d-65d2fdaf3fdc | D10: • Built audit logging and role-based access into 6 features in a regulated bank environment; passed internal audit with zero findings on my services. • Built a Python service that extracts fields from settlement PDFs with an LLM plus rule-based validation, hitting 90% field accuracy on 300 labeled documents. • Created an LLM evaluation harness (300 labeled cases, regression checks) that blocked 4 quality regressions pre-release. • Use Claude Code and Copilot daily; tracked my PR cycle time over a quarter (3 days to 1.8) and wrote review guidelines for AI-generated code. • Turned 12 compliance policy rules into automated pre-merge checks, replacing a manual review that took 3 hours/week. | E10: =AVERAGEIFS('Validation (Final)'!$L$2:$L$281,'Validation (Final)'!$A$2:$A$281,A10,'Validation (Final)'!$B$2:$B$281,B10) -> 8.07 | F10: =AVERAGEIFS('Validation (Final)'!$M$2:$M$281,'Validation (Final)'!$A$2:$A$281,A10,'Validation (Final)'!$B$2:$B$281,B10) -> 7.18 | G10: 2027 new-grad cohort; likely requires upcoming graduation. Long shot. | H10: Original 14 (full revision history)
A11: Replit | B11: Software Engineer - New Grad (2027) | C11: https://jobs.ashbyhq.com/replit/b5e81eae-06f9-4798-8988-2d06ca936dbc | D11: • Built an internal ops tool used by 60 engineers/analysts, cutting exception-resolution time from 20 to 7 minutes. • Shipped the exceptions dashboard's 6 core features on weekly releases, reaching 85% weekly adoption in a month; prototyped UI variants with Claude Code in hours. • Built AI-assisted workflows (codegen, test generation, PR summaries) adopted by 8 teammates, saving ~5 hrs/week each. • Built a CLI that replays payment events in test environments; 6 engineers on 2 teams use it, cutting bug-repro from 2 hours to 15 minutes. • Traced a recurring dashboard timeout to an N+1 query; the fix cut error rate from 2% to 0.3% and ended weekly escalations. | E11: =AVERAGEIFS('Validation (Final)'!$L$2:$L$281,'Validation (Final)'!$A$2:$A$281,A11,'Validation (Final)'!$B$2:$B$281,B11) -> 7.74 | F11: =AVERAGEIFS('Validation (Final)'!$M$2:$M$281,'Validation (Final)'!$A$2:$A$281,A11,'Validation (Final)'!$B$2:$B$281,B11) -> 7.09 | G11: 2027 new-grad cohort; likely requires upcoming graduation. Long shot. | H11: Original 14 (full revision history)
A12: Cursor (Anysphere) | B12: Software Engineer, New Grad 2027 | C12: https://jobs.ashbyhq.com/cursor/d0e5b41d-84ab-4887-bd3a-55589b11dd7b | D12: • Ship daily with AI coding agents (Claude Code, Copilot); my PR throughput rose ~40% over a quarter while defect escapes stayed flat. • Built a prompt/eval pipeline testing LLM outputs on 300 labeled cases, catching 4 regressions before release. • Cut settlement-API p99 from 620ms to 210ms through profiling and query/caching changes. • Built a CLI that replays payment events in test environments, cutting bug-repro from 2 hours to 15 minutes for 6 engineers. • Added 140 integration tests and latency/error telemetry to every service I shipped, catching 9 staging regressions; AI drafted the tests, I hand-verified each. | E12: =AVERAGEIFS('Validation (Final)'!$L$2:$L$281,'Validation (Final)'!$A$2:$A$281,A12,'Validation (Final)'!$B$2:$B$281,B12) -> 8.02 | F12: =AVERAGEIFS('Validation (Final)'!$M$2:$M$281,'Validation (Final)'!$A$2:$A$281,A12,'Validation (Final)'!$B$2:$B$281,B12) -> 7.19 | G12: Wants Spring 2027 grads + open/reviewable shipped project. Long shot. | H12: Original 14 (full revision history)
A13: Notion | B13: Software Engineer, New Grad (Dec 2026) | C13: https://jobs.ashbyhq.com/notion/e32799d2-8ef8-4803-8189-c72514afa816 | D13: • Built React/TypeScript features for the 60-user exceptions dashboard, reaching 85% weekly adoption within a month. • Improved UI load time from 8s to 1.5s via query batching, pagination, and lazy loading. • Found 3 unused views via dashboard analytics, removed them, and lifted weekly active use from 55% to 85%. • Cut React component and test scaffolding time ~50% with Copilot/Claude Code templates; shared the prompts with 8 teammates. • Shipped the exceptions workflow in 5 weeks after 3 usability rounds with 8 ops users; task time dropped from 20 to 7 minutes. | E13: =AVERAGEIFS('Validation (Final)'!$L$2:$L$281,'Validation (Final)'!$A$2:$A$281,A13,'Validation (Final)'!$B$2:$B$281,B13) -> 7.61 | F13: =AVERAGEIFS('Validation (Final)'!$M$2:$M$281,'Validation (Final)'!$A$2:$A$281,A13,'Validation (Final)'!$B$2:$B$281,B13) -> 6.9 | G13: Requires graduating by Dec 2026 + prior internship. Likely ineligible. | H13: Original 14 (full revision history)
... A15: Zip | B15: Software Engineer, New Grad (2027 Start) | C15: https://jobs.ashbyhq.com/zip/df6eb1ee-b360-46fe-b23f-658626ec59ea/application | D15: • Built exception-approval workflow features for 60 ops users, automating 70% of manual steps and cutting resolution time from 20 to 7 minutes. • Integrated 5 upstream systems via REST/Kafka with schema validation, cutting malformed-message failures from 3% to 0.2%. • Cut exception-resolution time from 20 to 7 minutes by redesigning the workflow and adding alerts. • Added role-based access and audit trails to 4 services, passing internal compliance review with no rework. • Prototyped an LLM agent to extract and classify requests, hitting 87% accuracy vs. manual baseline. | E15: =AVERAGEIFS('Validation (Final)'!$L$2:$L$281,'Validation (Final)'!$A$2:$A$281,A15,'Validation (Final)'!$B$2:$B$281,B15) -> 7.66 | F15: =AVERAGEIFS('Validation (Final)'!$M$2:$M$281,'Validation (Final)'!$A$2:$A$281,A15,'Validation (Final)'!$B$2:$B$281,B15) -> 7.47 | G15: Asks for Dec 2026-Jun 2027 graduation. Likely ineligible. | H15: Original 14 (full revision history)
A16: Plaid | B16: Software Engineer, Backend | C16: https://jobs.ashbyhq.com/plaid/5c5d4414-347c-4caa-be88-384dec2d074b | D16: • Fixed a duplicate-posting bug class by designing idempotency keys for settlement retries, eliminating ~120 duplicate transactions/month. • Cut p99 latency of the settlement-status API from 620ms to 210ms by adding a Redis cache and rewriting 3 slow Oracle queries. • Migrated 9 nightly batch jobs to Kafka event-driven services, cutting end-to-end settlement processing from 4 hours to 25 minutes. • Added reconciliation checks and audit logging that caught 14 ledger mismatches before customers saw them. • Built an LLM script to triage failed-payment tickets (87% accuracy on 300 labeled tickets), saving the team ~6 hrs/week. | E16: =AVERAGEIFS('Validation (Final)'!$L$2:$L$281,'Validation (Final)'!$A$2:$A$281,A16,'Validation (Final)'!$B$2:$B$281,B16) -> 7.76 | F16: n/a | G16: Posting asks 1-4 yrs post-internship: strong fit; fintech infrastructure. | H16: Reused: Backend / fintech
A17: Traba | B17: Software Engineer (AI Agents) | C17: https://jobs.ashbyhq.com/traba/e1761ab2-21f1-46d6-8c69-9b4a73d9430f | D17: • Ship daily with AI coding agents (Claude Code, Copilot); my PR throughput rose ~40% over a quarter while defect escapes stayed flat. • Built a prompt/eval pipeline testing LLM outputs on 300 labeled cases, catching 4 regressions before release. • Use Claude Code and Copilot daily; tracked my PR cycle time over a quarter (3 days to 1.8) and wrote review guidelines for AI-generated code. • Built an LLM triage script (87% on 300 labeled tickets) saving ~6 hrs/week; AI coding tools cut my feature cycle time ~30%. • Prototyped natural-language querying over exception data with an LLM, measured at 87% accuracy on a 300-case eval set. | E17: =AVERAGEIFS('Validation (Final)'!$L$2:$L$281,'Validation (Final)'!$A$2:$A$281,A17,'Validation (Final)'!$B$2:$B$281,B17) -> 8.07 | F17: n/a | G17: Asks ~1+ yr shipping LLM features; founding-team style role. | H17: Reused: AI / agents
A18: Serval | B18: Software Engineer, Applied AI | C18: https://jobs.ashbyhq.com/serval/2bfaede4-22b2-43b2-a14c-f45e5f398624 | D18: • Created an LLM evaluation harness (300 labeled cases, regression checks) that blocked 4 quality regressions pre-release. • Built a prompt/eval pipeline testing LLM outputs on 300 labeled cases, catching 4 regressions before release. • Built an LLM triage assistant that classifies failed jobs and proposes fixes; engineers accepted its suggestion in ~35% of cases during a 4-week pilot. • Built AI-assisted workflows (codegen, test generation, PR summaries) adopted by 8 teammates, saving ~5 hrs/week each. • Prototyped an LLM workflow for ticket triage with human-in-loop review, reaching 87% accuracy. | E18: =AVERAGEIFS('Validation (Final)'!$L$2:$L$281,'Validation (Final)'!$A$2:$A$281,A18,'Validation (Final)'!$B$2:$B$281,B18) -> 8.23 | F18: n/a | G18: YOE not confirmed; IT-workflow agents. Check level before applying. | H18: Reused: AI / agents
A19: LiveFlow | B19: Software Engineer - AI Agents | C19: https://jobs.ashbyhq.com/liveflow/e1ba2bad-030a-4bc2-9bbd-f1375f712a57 | D19: • Built an LLM triage assistant that classifies failed jobs and proposes fixes; engineers accepted its suggestion in ~35% of cases during a 4-week pilot. • Built a Python service that extracts fields from settlement PDFs with an LLM plus rule-based validation, hitting 90% field accuracy on 300 labeled documents. • Created an LLM evaluation harness (300 labeled cases, regression checks) that blocked 4 quality regressions pre-release. • Built an LLM script to triage failed-payment tickets (87% accuracy on 300 labeled tickets), saving the team ~6 hrs/week. • Lifted unit-test coverage on owned services from 52% to 81% in 3 weeks, using Copilot/Claude Code to draft tests I reviewed by hand. | E19: =AVERAGEIFS('Validation (Final)'!$L$2:$L$281,'Validation (Final)'!$A$2:$A$281,A19,'Validation (Final)'!$B$2:$B$281,B19) -> 7.93 | F19: n/a | G19: Full-stack on AI agents for finance/accounting software (SF hybrid): domain overlaps JPMC. | H19: Reused: AI / agents
A20: Hilbert's AI | B20: Software Engineer (Full-Stack / Product) | C20: https://jobs.ashbyhq.com/hilberts/989d547f-1f23-43b9-b8e8-c8771d7d4286 | D20: • Built React/TypeScript features for the 60-user exceptions dashboard, reaching 85% weekly adoption within a month. • Built AI-assisted workflows (codegen, test generation, PR summaries) adopted by 8 teammates, saving ~5 hrs/week each. • Built a prompt/eval pipeline testing LLM outputs on 300 labeled cases, catching 4 regressions before release. • Introduced OpenAPI contracts across 3 frontend/backend teams and generated typed clients, cutting integration bugs 40%. • Prototyped natural-language querying over exception data with an LLM, measured at 87% accuracy on a 300-case eval set. | E20: =AVERAGEIFS('Validation (Final)'!$L$2:$L$281,'Validation (Final)'!$A$2:$A$281,A20,'Validation (Final)'!$B$2:$B$281,B20) -> 7.76 | F20: n/a | G20: TypeScript/Node/React on an agentic interface; SF or Istanbul. | H20: Reused: Full stack + AI
A21: The Flex | B21: Full-Stack Product Engineer | C21: https://jobs.ashbyhq.com/The-Flex/82eafc9b-c4c0-4310-8b9d-9f5410ff0d53 | D21: • Built exception-approval workflow features for 60 ops users, automating 70% of manual steps and cutting resolution time from 20 to 7 minutes. • Cut exception-resolution time from 20 to 7 minutes by redesigning the workflow and adding alerts. • Owned the settlement-exceptions dashboard from design doc to production, using feature flags and monitoring for a zero-downtime rollout to 60 users. • Shipped the exceptions workflow in 5 weeks after 3 usability rounds with 8 ops users; task time dropped from 20 to 7 minutes. • Wrote an AI-assisted dev playbook for 8 teammates; PR cycle time fell from 3 days to 1.8 with review standards unchanged. | E21: =AVERAGEIFS('Validation (Final)'!$L$2:$L$281,'Validation (Final)'!$A$2:$A$281,A21,'Validation (Final)'!$B$2:$B$281,B21) -> 7.45 | F21: n/a | G21: Python/FastAPI/React/TS; internal tools + Stripe/Twilio integrations. | H21: Reused: Full stack
A22: Pivotal Health | B22: Full Stack Product Engineer | C22: https://jobs.ashbyhq.com/pivotal-health/74f89bd9-30ca-4cf9-ab50-e0f1d2af2431 | D22: • Built full-stack features (React/TypeScript + Java APIs) for a 60-user internal ops dashboard used to monitor settlement exceptions. • Cut dashboard load time from 8s to 1.5s via query optimization and pagination over 20M-row tables. • Designed a pipeline normalizing 5 upstream data feeds into one schema, eliminating ~10 hrs/week of manual reconciliation. • Shipped 6 features end-to-end (React, REST, Oracle) for the exceptions dashboard, lifting weekly active use from 55% to 85%. • Prototyped natural-language querying over exception data with an LLM, measured at 87% accuracy on a 300-case eval set. | E22: =AVERAGEIFS('Validation (Final)'!$L$2:$L$281,'Validation (Final)'!$A$2:$A$281,A22,'Validation (Final)'!$B$2:$B$281,B22) -> 7.61 | F22: n/a | G22: Backend-leaning, AI/ML team. Pay band suggests mid-senior: check YOE. | H22: Reused: Full stack
A23: Applied Intuition | B23: Software Engineer - AI Engineering | C23: https://jobs.ashbyhq.com/applied/981054d6-d6d9-4553-9db8-38e56939d3b8 | D23: • Created an LLM evaluation harness (300 labeled cases, regression checks) that blocked 4 quality regressions pre-release. • Built a prompt/eval pipeline testing LLM outputs on 300 labeled cases, catching 4 regressions before release. • Built an LLM triage assistant that classifies failed jobs and proposes fixes; engineers accepted its suggestion in ~35% of cases during a 4-week pilot. • Built AI-assisted workflows (codegen, test generation, PR summaries) adopted by 8 teammates, saving ~5 hrs/week each. • Prototyped an LLM workflow for ticket triage with human-in-loop review, reaching 87% accuracy. | E23: =AVERAGEIFS('Validation (Final)'!$L$2:$L$281,'Validation (Final)'!$A$2:$A$281,A23,'Validation (Final)'!$B$2:$B$281,B23) -> 8.23 | F23: n/a | G23: Asks 2+ yrs AI/ML feature experience: stretch. | H23: Reused: AI / agents
A24: Perplexity | B24: Member of Technical Staff (Software Engineer, Applied AI) | C24: https://jobs.ashbyhq.com/perplexity/3c656963-876a-458d-bca6-916a42a24c1a | D24: • Ship daily with AI coding agents (Claude Code, Copilot); my PR throughput rose ~40% over a quarter while defect escapes stayed flat. • Built a prompt/eval pipeline testing LLM outputs on 300 labeled cases, catching 4 regressions before release. • Use Claude Code and Copilot daily; tracked my PR cycle time over a quarter (3 days to 1.8) and wrote review guidelines for AI-generated code. • Built an LLM triage script (87% on 300 labeled tickets) saving ~6 hrs/week; AI coding tools cut my feature cycle time ~30%. • Prototyped natural-language querying over exception data with an LLM, measured at 87% accuracy on a 300-case eval set. | E24: =AVERAGEIFS('Validation (Final)'!$L$2:$L$281,'Validation (Final)'!$A$2:$A$281,A24,'Validation (Final)'!$B$2:$B$281,B24) -> 8.07 | F24: n/a | G24: YOE not stated in results; agent work. Stretch. | H24: Reused: AI / agents
A25: Smartsheet | B25: Software Engineer II - Full Stack (Remote Eligible) | C25: https://job-boards.greenhouse.io/smartsheet/jobs/8097667 | D25: • Designed async retry + dead-letter handling that raised job success rate from 96.8% to 99.7%. • Cut p99 latency of the settlement-status API from 620ms to 210ms by adding a Redis cache and rewriting 3 slow Oracle queries. • Built Grafana/Splunk alerting that cut mean-time-to-detect from 25 to 6 minutes across 4 distributed services. • Built distributed Java services on AWS (ECS, SQS) handling 38M events/day; autoscaling cut compute cost 22%. • Built an LLM script to triage failed-payment tickets (87% accuracy on 300 labeled tickets), saving the team ~6 hrs/week. | E25: =AVERAGEIFS('Validation (Final)'!$L$2:$L$281,'Validation (Final)'!$A$2:$A$281,A25,'Validation (Final)'!$B$2:$B$281,B25) -> 7.6 | F25: n/a | G25: Asks 2+ yrs Java/Kotlin/TS + AWS/K8s: your Java stack matches. | H25: Reused: Backend / cloud
A26: Conga | B26: Software Engineer II - Full Stack | C26: https://job-boards.greenhouse.io/conga/jobs/5116390007 | D26: • Built full-stack features (React/TypeScript + Java APIs) for a 60-user internal ops dashboard used to monitor settlement exceptions. • Cut dashboard load time from 8s to 1.5s via query optimization and pagination over 20M-row tables. • Designed a pipeline normalizing 5 upstream data feeds into one schema, eliminating ~10 hrs/week of manual reconciliation. • Shipped 6 features end-to-end (React, REST, Oracle) for the exceptions dashboard, lifting weekly active use from 55% to 85%. • Prototyped natural-language querying over exception data with an LLM, measured at 87% accuracy on a 300-case eval set. | E26: =AVERAGEIFS('Validation (Final)'!$L$2:$L$281,'Validation (Final)'!$A$2:$A$281,A26,'Validation (Final)'!$B$2:$B$281,B26) -> 7.61 | F26: n/a | G26: Asks 2+ yrs OO development (Java); Houston hybrid. | H26: Reused: Full stack
A27: Zip Co Limited | B27: Software Engineer II (Full Stack) | C27: https://job-boards.greenhouse.io/zipcolimited/jobs/4564108006 | D27: • Built React/TypeScript features for the 60-user exceptions dashboard, reaching 85% weekly adoption within a month. • Improved UI load time from 8s to 1.5s via query batching, pagination, and lazy loading. • Built an internal ops tool used by 60 engineers/analysts, cutting exception-resolution time from 20 to 7 minutes. • Introduced OpenAPI contracts across 3 frontend/backend teams and generated typed clients, cutting integration bugs 40%. • Built AI-assisted workflows (codegen, test generation, PR summaries) adopted by 8 teammates, saving ~5 hrs/week each. | E27: =AVERAGEIFS('Validation (Final)'!$L$2:$L$281,'Validation (Final)'!$A$2:$A$281,A27,'Validation (Final)'!$B$2:$B$281,B27) -> 7.55 | F27: n/a | G27: Innovation Labs; .NET Core + React, so stack differs from Java. | H27: Reused: Full stack
... A57: Google | B57: Software Engineer II, Android | C57: https://www.google.com/about/careers/applications/jobs/results/77784007952999110-software-engineer-ii/ | D57: • Cut p99 latency of the settlement-status API from 620ms to 210ms by adding a Redis cache and rewriting 3 slow Oracle queries. • Fixed a duplicate-posting bug class by designing idempotency keys for settlement retries, eliminating ~120 duplicate transactions/month. • Cut dashboard load time from 8s to 1.5s via query optimization and pagination over 20M-row tables. • Built a CLI that replays payment events in test environments, cutting bug-repro from 2 hours to 15 minutes for 6 engineers. • Wrote an AI-assisted dev playbook for 8 teammates; PR cycle time fell from 3 days to 1.8 with review standards unchanged. | E57: =AVERAGEIFS('Validation (Final)'!$L$2:$L$281,'Validation (Final)'!$A$2:$A$281,A57,'Validation (Final)'!$B$2:$B$281,B57) -> 7.79 | F57: n/a | G57: ~1 yr programming typical. | H57: Reused: Early career

Sheet Round Summary
A1: Round | B1: Bullets revised | C1: Mean score of all 70 bullets (/10) | D1: Bullets >= 8.0 | E1: Bullets >= 7.5 | F1: Lowest score
A2: 0 | B2: 0 | C2: =AVERAGE('Round State'!B2:B71) -> 7.1464286 | D2: =COUNTIF('Round State'!B2:B71,">=8") -> 10 | E2: =COUNTIF('Round State'!B2:B71,">=7.5") -> 25 | F2: =MIN('Round State'!B2:B71) -> 5.1
A3: 1 | B3: 21 | C3: =AVERAGE('Round State'!C2:C71) -> 7.4428571 | D3: =COUNTIF('Round State'!C2:C71,">=8") -> 13 | E3: =COUNTIF('Round State'!C2:C71,">=7.5") -> 31 | F3: =MIN('Round State'!C2:C71) -> 6.6
A4: 2 | B4: 32 | C4: =AVERAGE('Round State'!D2:D71) -> 7.6292857 | D4: =COUNTIF('Round State'!D2:D71,">=8") -> 14 | E4: =COUNTIF('Round State'!D2:D71,">=7.5") -> 44 | F4: =MIN('Round State'!D2:D71) -> 6.8
A5: 3 | B5: 22 | C5: =AVERAGE('Round State'!E2:E71) -> 7.6985714 | D5: =COUNTIF('Round State'!E2:E71,">=8") -> 15 | E5: =COUNTIF('Round State'!E2:E71,">=7.5") -> 55 | F5: =MIN('Round State'!E2:E71) -> 7.15
A7: Round 0 = baseline draft with illustrative numbers. Each later round: self-critique the lowest-scoring bullets, rewrite, rescore. Scores are my own judgment against the rubric, not an objective measure; later gains shrink because the AI-fluency dimension limits bullets where AI isn't relevant (see Rubric tab, suggestion 2). Round figures cover the original 14 roles (70 bullets). The 42 roles added later reuse these final bullets matched to the role's profile; their JD-Alignment score is the source bullet's minus 1, because the bullet was not written for that exact posting. Tailor the wording to each JD before applying.

Sheet Rubric
A1: Rubric v2 (7 dimensions, weighted). Blue cells are editable inputs; every score in the workbook recalculates from them.
A3: Dimension | B3: Weight | C3: What a 10 looks like | D3: Why it matters for getting interviews
A4: Concise & Punchy | B4: 0.1 | C4: One line, strong verb first, result visible in the first 8 words. | D4: Recruiters skim a resume in ~7 seconds; long bullets get skipped.
A5: Overall Impact | B5: 0.2 | C5: Measurable outcome tied to users, money, reliability or speed. | D5: Outcomes, not duties, separate shortlisted resumes.
A6: Realistic for ~1 YOE | B6: 0.2 | C6: Scope is believable for ~15 months: owned a feature/service, not an org. | D6: Over-claiming gets exposed in the phone screen and sinks you.
A7: AI-Native Fluency | B7: 0.1 | C7: Shows concrete AI-assisted workflow or LLM work with measurement and human review. | D7: AI-first employers screen for it; matters less at traditional shops.
A8: JD Alignment | B8: 0.15 | C8: Mirrors this role's stack, domain and keywords (NEW vs v1). | D8: ATS and recruiters match on keywords; same bullet scores differently per job.
A9: Credibility / Defensible | B9: 0.15 | C9: Every number can be explained in 60 seconds in an interview (NEW). | D9: Interviewers probe each metric; undefendable numbers are the top rejection cause.
A10: Interview Hook | B10: 0.1 | C10: Contains a decision, trade-off or story that invites a follow-up question (NEW). | D10: Bullets are conversation starters; the interview IS the goal.
A12: Gate threshold | B12: 7 | C12: If Realistic OR Credibility scores below this, a penalty applies.
A13: Gate penalty (points) | B13: 1 | C13: Subtracted from the weighted score. Prevents a flashy but undefendable bullet from ranking high.
A14: Weights total (must be 1.00) | B14: =SUM(B4:B10) -> 1
A16: Suggested rubric improvements (my recommendations)
A17: 1. Score against the specific job description, not in a vacuum. 'JD Alignment' is now a dimension; before applying, rerun it per posting.
A18: 2. Make AI-fluency weight role-dependent: ~20% for Cursor/Replit/Harvey-type AI-first companies, ~5% for Mastercard/Amazon. Right now it caps non-AI bullets near 7.7-8; set weights per company in the Rubric tab to see the effect.
A19: 3. Score Credibility from an interviewer's viewpoint: could you explain the number, the baseline and the measurement method in 60 seconds? If not, cut it.
A20: 4. Add an ATS-keyword check (exact stack terms from the JD: e.g., Kafka, Terraform, React). Not scored here because it needs the full JD text.
A21: 5. Score the full resume, not bullets in isolation: variety (not 5 latency bullets), and no repeated claim across roles.
A22: 6. Replace self-scoring with outside signal: have 2-3 engineers or a recruiter rate the top bullets blind, and track which versions actually get recruiter replies.
A23: 7. Interview conversion is the true metric: after ~15 applications compare callback rates by bullet style and re-weight the rubric to match.

Sheet Validation (Final)
A1: Company | B1: Role | C1: Bullet # | D1: Final Bullet (illustrative numbers) | E1: Concise & Punchy | F1: Overall Impact | G1: Realistic for ~1 YOE | H1: AI-Native Fluency | I1: JD Alignment | J1: Credibility | K1: Interview Hook | L1: Final Score (/10) | M1: Baseline Score (/10) | N1: Change | O1: Key
A2: Amazon (Twitch) | B2: Software Engineer I (Seattle) | C2: 1 | D2: Own 4 Java/Spring Boot services in JPMC's payment-authorization platform on AWS (38M transactions/day, 99.95% availability); led the zero-downtime Java 17 upgrade. | E2: 7 | F2: 8 | G2: 8 | H2: 4 | I2: 8 | J2: 8 | K2: 8 | L2: =ROUND(E2*Rubric!$B$4+F2*Rubric!$B$5+G2*Rubric!$B$6+H2*Rubric!$B$7+I2*Rubric!$B$8+J2*Rubric!$B$9+K2*Rubric!$B$10-IF(OR(G2<Rubric!$B$12,J2<Rubric!$B$12),Rubric!$B$13,0),2) -> 7.5 | M2: =SUMIFS('Revision Log'!$M:$M,'Revision Log'!$N:$N,O2,'Revision Log'!$C:$C,0) -> 7.2 | N2: =L2-M2 -> 0.3 | O2: 0
A3: Amazon (Twitch) | B3: Software Engineer I (Seattle) | C3: 2 | D3: Cut p99 latency of the settlement-status API from 620ms to 210ms by adding a Redis cache and rewriting 3 slow Oracle queries. | E3: 9 | F3: 9 | G3: 8 | H3: 4 | I3: 8 | J3: 9 | K3: 8 | L3: =ROUND(E3*Rubric!$B$4+F3*Rubric!$B$5+G3*Rubric!$B$6+H3*Rubric!$B$7+I3*Rubric!$B$8+J3*Rubric!$B$9+K3*Rubric!$B$10-IF(OR(G3<Rubric!$B$12,J3<Rubric!$B$12),Rubric!$B$13,0),2) -> 8.05 | M3: =SUMIFS('Revision Log'!$M:$M,'Revision Log'!$N:$N,O3,'Revision Log'!$C:$C,0) -> 8.05 | N3: =L3-M3 -> 0 | O3: 1
A4: Amazon (Twitch) | B4: Software Engineer I (Seattle) | C4: 3 | D4: Built CI/CD with automated integration tests, moving releases from bi-weekly to on-demand and cutting rollbacks from 12% to 3%. | E4: 9 | F4: 8 | G4: 8 | H4: 4 | I4: 7 | J4: 8 | K4: 7 | L4: =ROUND(E4*Rubric!$B$4+F4*Rubric!$B$5+G4*Rubric!$B$6+H4*Rubric!$B$7+I4*Rubric!$B$8+J4*Rubric!$B$9+K4*Rubric!$B$10-IF(OR(G4<Rubric!$B$12,J4<Rubric!$B$12),Rubric!$B$13,0),2) -> 7.45 | M4: =SUMIFS('Revision Log'!$M:$M,'Revision Log'!$N:$N,O4,'Revision Log'!$C:$C,0) -> 7.25 | N4: =L4-M4 -> 0.2 | O4: 2
A5: Amazon (Twitch) | B5: Software Engineer I (Seattle) | C5: 4 | D5: On-call for 4 services; Grafana/Splunk alerts and runbooks cut mean-time-to-detect from 25 to 6 minutes and halved repeat pages. | E5: 9 | F5: 8 | G5: 8 | H5: 3 | I5: 7 | J5: 8 | K5: 7 | L5: =ROUND(E5*Rubric!$B$4+F5*Rubric!$B$5+G5*Rubric!$B$6+H5*Rubric!$B$7+I5*Rubric!$B$8+J5*Rubric!$B$9+K5*Rubric!$B$10-IF(OR(G5<Rubric!$B$12,J5<Rubric!$B$12),Rubric!$B$13,0),2) -> 7.35 | M5: =SUMIFS('Revision Log'!$M:$M,'Revision Log'!$N:$N,O5,'Revision Log'!$C:$C,0) -> 6.95 | N5: =L5-M5 -> 0.4 | O5: 3
A6: Amazon (Twitch) | B6: Software Engineer I (Seattle) | C6: 5 | D6: Lifted unit-test coverage on owned services from 52% to 81% in 3 weeks, using Copilot/Claude Code to draft tests I reviewed by hand. | E6: 9 | F6: 7 | G6: 8 | H6: 8 | I6: 7 | J6: 8 | K6: 7 | L6: =ROUND(E6*Rubric!$B$4+F6*Rubric!$B$5+G6*Rubric!$B$6+H6*Rubric!$B$7+I6*Rubric!$B$8+J6*Rubric!$B$9+K6*Rubric!$B$10-IF(OR(G6<Rubric!$B$12,J6<Rubric!$B$12),Rubric!$B$13,0),2) -> 7.65 | M6: =SUMIFS('Revision Log'!$M:$M,'Revision Log'!$N:$N,O6,'Revision Log'!$C:$C,0) -> 7.4 | N6: =L6-M6 -> 0.25 | O6: 4
A7: Amazon | B7: Software Engineer I, Payments | C7: 1 | D7: Shipped 6 features to a $1.2B/day payment platform via 10%-to-100% staged rollouts and feature flags, with zero Sev-1 incidents. | E7: 9 | F7: 7 | G7: 7 | H7: 3 | I7: 9 | J7: 8 | K7: 8 | L7: =ROUND(E7*Rubric!$B$4+F7*Rubric!$B$5+G7*Rubric!$B$6+H7*Rubric!$B$7+I7*Rubric!$B$8+J7*Rubric!$B$9+K7*Rubric!$B$10-IF(OR(G7<Rubric!$B$12,J7<Rubric!$B$12),Rubric!$B$13,0),2) -> 7.35 | M7: =SUMIFS('Revision Log'!$M:$M,'Revision Log'!$N:$N,O7,'Revision Log'!$C:$C,0) -> 5.75 | N7: =L7-M7 -> 1.6 | O7: 10
A8: Amazon | B8: Software Engineer I, Payments | C8: 2 | D8: Fixed a duplicate-posting bug class by designing idempotency keys for settlement retries, eliminating ~120 duplicate transactions/month. | E8: 9 | F8: 9 | G8: 8 | H8: 3 | I8: 9 | J8: 9 | K8: 9 | L8: =ROUND(E8*Rubric!$B$4+F8*Rubric!$B$5+G8*Rubric!$B$6+H8*Rubric!$B$7+I8*Rubric!$B$8+J8*Rubric!$B$9+K8*Rubric!$B$10-IF(OR(G8<Rubric!$B$12,J8<Rubric!$B$12),Rubric!$B$13,0),2) -> 8.2 | M8: =SUMIFS('Revision Log'!$M:$M,'Revision Log'!$N:$N,O8,'Revision Log'!$C:$C,0) -> 8.2 | N8: =L8-M8 -> 0 | O8: 11
A9: Amazon | B9: Software Engineer I, Payments | C9: 3 | D9: Migrated 9 nightly batch jobs to Kafka event-driven services, cutting end-to-end settlement processing from 4 hours to 25 minutes. | E9: 9 | F9: 9 | G9: 7 | H9: 3 | I9: 8 | J9: 9 | K9: 9 | L9: =ROUND(E9*Rubric!$B$4+F9*Rubric!$B$5+G9*Rubric!$B$6+H9*Rubric!$B$7+I9*Rubric!$B$8+J9*Rubric!$B$9+K9*Rubric!$B$10-IF(OR(G9<Rubric!$B$12,J9<Rubric!$B$12),Rubric!$B$13,0),2) -> 7.85 | M9: =SUMIFS('Revision Log'!$M:$M,'Revision Log'!$N:$N,O9,'Revision Log'!$C:$C,0) -> 7.85 | N9: =L9-M9 -> 0 | O9: 12
A10: Amazon | B10: Software Engineer I, Payments | C10: 4 | D10: Added reconciliation checks and audit logging that caught 14 ledger mismatches before customers saw them. | E10: 9 | F10: 8 | G10: 8 | H10: 3 | I10: 8 | J10: 8 | K10: 8 | L10: =ROUND(E10*Rubric!$B$4+F10*Rubric!$B$5+G10*Rubric!$B$6+H10*Rubric!$B$7+I10*Rubric!$B$8+J10*Rubric!$B$9+K10*Rubric!$B$10-IF(OR(G10<Rubric!$B$12,J10<Rubric!$B$12),Rubric!$B$13,0),2) -> 7.6 | M10: =SUMIFS('Revision Log'!$M:$M,'Revision Log'!$N:$N,O10,'Revision Log'!$C:$C,0) -> 7.5 | N10: =L10-M10 -> 0.1 | O10: 13
A11: Amazon | B11: Software Engineer I, Payments | C11: 5 | D11: Built an LLM script to triage failed-payment tickets (87% accuracy on 300 labeled tickets), saving the team ~6 hrs/week. | E11: 8 | F11: 8 | G11: 7 | H11: 9 | I11: 7 | J11: 8 | K11: 9 | L11: =ROUND(E11*Rubric!$B$4+F11*Rubric!$B$5+G11*Rubric!$B$6+H11*Rubric!$B$7+I11*Rubric!$B$8+J11*Rubric!$B$9+K11*Rubric!$B$10-IF(OR(G11<Rubric!$B$12,J11<Rubric!$B$12),Rubric!$B$13,0),2) -> 7.85 | M11: =SUMIFS('Revision Log'!$M:$M,'Revision Log'!$N:$N,O11,'Revision Log'!$C:$C,0) -> 7.85 | N11: =L11-M11 -> 0 | O11: 14
A12: Mastercard | B12: Software Engineer I (O'Fallon, MO) | C12: 1 | D12: Maintain 4 Java services in a 38M-events/day transaction pipeline at 99.95% availability, including on-call. | E12: 8 | F12: 7 | G12: 9 | H12: 2 | I12: 9 | J12: 8 | K12: 6 | L12: =ROUND(E12*Rubric!$B$4+F12*Rubric!$B$5+G12*Rubric!$B$6+H12*Rubric!$B$7+I12*Rubric!$B$8+J12*Rubric!$B$9+K12*Rubric!$B$10-IF(OR(G12<Rubric!$B$12,J12<Rubric!$B$12),Rubric!$B$13,0),2) -> 7.35 | M12: =SUMIFS('Revision Log'!$M:$M,'Revision Log'!$N:$N,O12,'Revision Log'!$C:$C,0) -> 7.05 | N12: =L12-M12 -> 0.3 | O12: 20
A13: Mastercard | B13: Software Engineer I (O'Fallon, MO) | C13: 2 | D13: Containerized 4 services and automated tests in CI, cutting build-and-deploy from 45 to 12 minutes and saving the team ~15 engineer-hours/month. | E13: 8 | F13: 8 | G13: 8 | H13: 3 | I13: 8 | J13: 8 | K13: 7 | L13: =ROUND(E13*Rubric!$B$4+F13*Rubric!$B$5+G13*Rubric!$B$6+H13*Rubric!$B$7+I13*Rubric!$B$8+J13*Rubric!$B$9+K13*Rubric!$B$10-IF(OR(G13<Rubric!$B$12,J13<Rubric!$B$12),Rubric!$B$13,0),2) -> 7.4 | M13: =SUMIFS('Revision Log'!$M:$M,'Revision Log'!$N:$N,O13,'Revision Log'!$C:$C,0) -> 6.95 | N13: =L13-M13 -> 0.45 | O13: 21
... A71: Zip | B71: Software Engineer, New Grad (2027 Start) | C71: 5 | D71: Prototyped an LLM agent to extract and classify requests, hitting 87% accuracy vs. manual baseline. | E71: 8 | F71: 8 | G71: 7 | H71: 9 | I71: 8 | J71: 8 | K71: 9 | L71: =ROUND(E71*Rubric!$B$4+F71*Rubric!$B$5+G71*Rubric!$B$6+H71*Rubric!$B$7+I71*Rubric!$B$8+J71*Rubric!$B$9+K71*Rubric!$B$10-IF(OR(G71<Rubric!$B$12,J71<Rubric!$B$12),Rubric!$B$13,0),2) -> 8 | M71: =SUMIFS('Revision Log'!$M:$M,'Revision Log'!$N:$N,O71,'Revision Log'!$C:$C,0) -> 8 | N71: =L71-M71 -> 0 | O71: 134
A72: Plaid | B72: Software Engineer, Backend | C72: 1 | D72: Fixed a duplicate-posting bug class by designing idempotency keys for settlement retries, eliminating ~120 duplicate transactions/month. | E72: 9 | F72: 9 | G72: 8 | H72: 3 | I72: 8 | J72: 9 | K72: 9 | L72: =ROUND(E72*Rubric!$B$4+F72*Rubric!$B$5+G72*Rubric!$B$6+H72*Rubric!$B$7+I72*Rubric!$B$8+J72*Rubric!$B$9+K72*Rubric!$B$10-IF(OR(G72<Rubric!$B$12,J72<Rubric!$B$12),Rubric!$B$13,0),2) -> 8.05 | M72: n/a | N72: n/a | O72: 1000
A73: Plaid | B73: Software Engineer, Backend | C73: 2 | D73: Cut p99 latency of the settlement-status API from 620ms to 210ms by adding a Redis cache and rewriting 3 slow Oracle queries. | E73: 9 | F73: 9 | G73: 8 | H73: 4 | I73: 7 | J73: 9 | K73: 8 | L73: =ROUND(E73*Rubric!$B$4+F73*Rubric!$B$5+G73*Rubric!$B$6+H73*Rubric!$B$7+I73*Rubric!$B$8+J73*Rubric!$B$9+K73*Rubric!$B$10-IF(OR(G73<Rubric!$B$12,J73<Rubric!$B$12),Rubric!$B$13,0),2) -> 7.9 | M73: n/a | N73: n/a | O73: 1001
A74: Plaid | B74: Software Engineer, Backend | C74: 3 | D74: Migrated 9 nightly batch jobs to Kafka event-driven services, cutting end-to-end settlement processing from 4 hours to 25 minutes. | E74: 9 | F74: 9 | G74: 7 | H74: 3 | I74: 7 | J74: 9 | K74: 9 | L74: =ROUND(E74*Rubric!$B$4+F74*Rubric!$B$5+G74*Rubric!$B$6+H74*Rubric!$B$7+I74*Rubric!$B$8+J74*Rubric!$B$9+K74*Rubric!$B$10-IF(OR(G74<Rubric!$B$12,J74<Rubric!$B$12),Rubric!$B$13,0),2) -> 7.7 | M74: n/a | N74: n/a | O74: 1002
A75: Plaid | B75: Software Engineer, Backend | C75: 4 | D75: Added reconciliation checks and audit logging that caught 14 ledger mismatches before customers saw them. | E75: 9 | F75: 8 | G75: 8 | H75: 3 | I75: 7 | J75: 8 | K75: 8 | L75: =ROUND(E75*Rubric!$B$4+F75*Rubric!$B$5+G75*Rubric!$B$6+H75*Rubric!$B$7+I75*Rubric!$B$8+J75*Rubric!$B$9+K75*Rubric!$B$10-IF(OR(G75<Rubric!$B$12,J75<Rubric!$B$12),Rubric!$B$13,0),2) -> 7.45 | M75: n/a | N75: n/a | O75: 1003
A76: Plaid | B76: Software Engineer, Backend | C76: 5 | D76: Built an LLM script to triage failed-payment tickets (87% accuracy on 300 labeled tickets), saving the team ~6 hrs/week. | E76: 8 | F76: 8 | G76: 7 | H76: 9 | I76: 6 | J76: 8 | K76: 9 | L76: =ROUND(E76*Rubric!$B$4+F76*Rubric!$B$5+G76*Rubric!$B$6+H76*Rubric!$B$7+I76*Rubric!$B$8+J76*Rubric!$B$9+K76*Rubric!$B$10-IF(OR(G76<Rubric!$B$12,J76<Rubric!$B$12),Rubric!$B$13,0),2) -> 7.7 | M76: n/a | N76: n/a | O76: 1004
A77: Traba | B77: Software Engineer (AI Agents) | C77: 1 | D77: Ship daily with AI coding agents (Claude Code, Copilot); my PR throughput rose ~40% over a quarter while defect escapes stayed flat. | E77: 8 | F77: 8 | G77: 7 | H77: 10 | I77: 9 | J77: 7 | K77: 9 | L77: =ROUND(E77*Rubric!$B$4+F77*Rubric!$B$5+G77*Rubric!$B$6+H77*Rubric!$B$7+I77*Rubric!$B$8+J77*Rubric!$B$9+K77*Rubric!$B$10-IF(OR(G77<Rubric!$B$12,J77<Rubric!$B$12),Rubric!$B$13,0),2) -> 8.1 | M77: n/a | N77: n/a | O77: 1010
A78: Traba | B78: Software Engineer (AI Agents) | C78: 2 | D78: Built a prompt/eval pipeline testing LLM outputs on 300 labeled cases, catching 4 regressions before release. | E78: 9 | F78: 8 | G78: 8 | H78: 10 | I78: 8 | J78: 8 | K78: 9 | L78: =ROUND(E78*Rubric!$B$4+F78*Rubric!$B$5+G78*Rubric!$B$6+H78*Rubric!$B$7+I78*Rubric!$B$8+J78*Rubric!$B$9+K78*Rubric!$B$10-IF(OR(G78<Rubric!$B$12,J78<Rubric!$B$12),Rubric!$B$13,0),2) -> 8.4 | M78: n/a | N78: n/a | O78: 1011
A79: Traba | B79: Software Engineer (AI Agents) | C79: 3 | D79: Use Claude Code and Copilot daily; tracked my PR cycle time over a quarter (3 days to 1.8) and wrote review guidelines for AI-generated code. | E79: 7 | F79: 8 | G79: 8 | H79: 10 | I79: 8 | J79: 8 | K79: 9 | L79: =ROUND(E79*Rubric!$B$4+F79*Rubric!$B$5+G79*Rubric!$B$6+H79*Rubric!$B$7+I79*Rubric!$B$8+J79*Rubric!$B$9+K79*Rubric!$B$10-IF(OR(G79<Rubric!$B$12,J79<Rubric!$B$12),Rubric!$B$13,0),2) -> 8.2 | M79: n/a | N79: n/a | O79: 1012
A80: Traba | B80: Software Engineer (AI Agents) | C80: 4 | D80: Built an LLM triage script (87% on 300 labeled tickets) saving ~6 hrs/week; AI coding tools cut my feature cycle time ~30%. | E80: 8 | F80: 8 | G80: 8 | H80: 9 | I80: 6 | J80: 8 | K80: 8 | L80: =ROUND(E80*Rubric!$B$4+F80*Rubric!$B$5+G80*Rubric!$B$6+H80*Rubric!$B$7+I80*Rubric!$B$8+J80*Rubric!$B$9+K80*Rubric!$B$10-IF(OR(G80<Rubric!$B$12,J80<Rubric!$B$12),Rubric!$B$13,0),2) -> 7.8 | M80: n/a | N80: n/a | O80: 1013
A81: Traba | B81: Software Engineer (AI Agents) | C81: 5 | D81: Prototyped natural-language querying over exception data with an LLM, measured at 87% accuracy on a 300-case eval set. | E81: 8 | F81: 8 | G81: 7 | H81: 9 | I81: 7 | J81: 8 | K81: 9 | L81: =ROUND(E81*Rubric!$B$4+F81*Rubric!$B$5+G81*Rubric!$B$6+H81*Rubric!$B$7+I81*Rubric!$B$8+J81*Rubric!$B$9+K81*Rubric!$B$10-IF(OR(G81<Rubric!$B$12,J81<Rubric!$B$12),Rubric!$B$13,0),2) -> 7.85 | M81: n/a | N81: n/a | O81: 1014
A82: Serval | B82: Software Engineer, Applied AI | C82: 1 | D82: Created an LLM evaluation harness (300 labeled cases, regression checks) that blocked 4 quality regressions pre-release. | E82: 9 | F82: 9 | G82: 7 | H82: 10 | I82: 9 | J82: 8 | K82: 10 | L82: =ROUND(E82*Rubric!$B$4+F82*Rubric!$B$5+G82*Rubric!$B$6+H82*Rubric!$B$7+I82*Rubric!$B$8+J82*Rubric!$B$9+K82*Rubric!$B$10-IF(OR(G82<Rubric!$B$12,J82<Rubric!$B$12),Rubric!$B$13,0),2) -> 8.65 | M82: n/a | N82: n/a | O82: 1020
A83: Serval | B83: Software Engineer, Applied AI | C83: 2 | D83: Built a prompt/eval pipeline testing LLM outputs on 300 labeled cases, catching 4 regressions before release. | E83: 9 | F83: 8 | G83: 8 | H83: 10 | I83: 8 | J83: 8 | K83: 9 | L83: =ROUND(E83*Rubric!$B$4+F83*Rubric!$B$5+G83*Rubric!$B$6+H83*Rubric!$B$7+I83*Rubric!$B$8+J83*Rubric!$B$9+K83*Rubric!$B$10-IF(OR(G83<Rubric!$B$12,J83<Rubric!$B$12),Rubric!$B$13,0),2) -> 8.4 | M83: n/a | N83: n/a | O83: 1021
... A281: Google | B281: Software Engineer II, Android | C281: 5 | D281: Wrote an AI-assisted dev playbook for 8 teammates; PR cycle time fell from 3 days to 1.8 with review standards unchanged. | E281: 8 | F281: 8 | G281: 8 | H281: 8 | I281: 6 | J281: 7 | K281: 8 | L281: =ROUND(E281*Rubric!$B$4+F281*Rubric!$B$5+G281*Rubric!$B$6+H281*Rubric!$B$7+I281*Rubric!$B$8+J281*Rubric!$B$9+K281*Rubric!$B$10-IF(OR(G281<Rubric!$B$12,J281<Rubric!$B$12),Rubric!$B$13,0),2) -> 7.55 | M281: n/a | N281: n/a | O281: 1414

Sheet Revision Log
A1: Company | B1: Role | C1: Round | D1: Bullet # | E1: Bullet text | F1: Concise | G1: Impact | H1: Realistic | I1: AI-Native | J1: JD Align | K1: Credibility | L1: Hook | M1: Score (/10) | N1: Key | O1: Self-critique driving this revision
A2: Amazon (Twitch) | B2: Software Engineer I (Seattle) | C2: 0 | D2: 1 | E2: Owned 4 Java/Spring Boot microservices in JPMC's payment-authorization platform on AWS, serving 38M transactions/day at 99.95% availability. | F2: 8 | G2: 7 | H2: 8 | I2: 4 | J2: 8 | K2: 8 | L2: 6 | M2: =ROUND(F2*Rubric!$B$4+G2*Rubric!$B$5+H2*Rubric!$B$6+I2*Rubric!$B$7+J2*Rubric!$B$8+K2*Rubric!$B$9+L2*Rubric!$B$10-IF(OR(H2<Rubric!$B$12,K2<Rubric!$B$12),Rubric!$B$13,0),2) -> 7.2 | N2: 0 | O2: Baseline draft with illustrative numbers.
A3: Amazon (Twitch) | B3: Software Engineer I (Seattle) | C3: 2 | D3: 1 | E3: Own 4 Java/Spring Boot services in JPMC's payment-authorization platform on AWS (38M transactions/day, 99.95% availability); led the zero-downtime Java 17 upgrade. | F3: 7 | G3: 8 | H3: 8 | I3: 4 | J3: 8 | K3: 8 | L3: 8 | M3: =ROUND(F3*Rubric!$B$4+G3*Rubric!$B$5+H3*Rubric!$B$6+I3*Rubric!$B$7+J3*Rubric!$B$8+K3*Rubric!$B$9+L3*Rubric!$B$10-IF(OR(H3<Rubric!$B$12,K3<Rubric!$B$12),Rubric!$B$13,0),2) -> 7.5 | N3: 0 | O3: No standout moment.
A4: Amazon (Twitch) | B4: Software Engineer I (Seattle) | C4: 0 | D4: 2 | E4: Cut p99 latency of the settlement-status API from 620ms to 210ms by adding a Redis cache and rewriting 3 slow Oracle queries. | F4: 9 | G4: 9 | H4: 8 | I4: 4 | J4: 8 | K4: 9 | L4: 8 | M4: =ROUND(F4*Rubric!$B$4+G4*Rubric!$B$5+H4*Rubric!$B$6+I4*Rubric!$B$7+J4*Rubric!$B$8+K4*Rubric!$B$9+L4*Rubric!$B$10-IF(OR(H4<Rubric!$B$12,K4<Rubric!$B$12),Rubric!$B$13,0),2) -> 8.05 | N4: 1 | O4: Baseline draft with illustrative numbers.
A5: Amazon (Twitch) | B5: Software Engineer I (Seattle) | C5: 0 | D5: 3 | E5: Built CI/CD pipeline with automated integration tests, moving releases from bi-weekly to on-demand and dropping rollback rate from 12% to 3%. | F5: 8 | G5: 8 | H5: 8 | I5: 4 | J5: 7 | K5: 8 | L5: 6 | M5: =ROUND(F5*Rubric!$B$4+G5*Rubric!$B$5+H5*Rubric!$B$6+I5*Rubric!$B$7+J5*Rubric!$B$8+K5*Rubric!$B$9+L5*Rubric!$B$10-IF(OR(H5<Rubric!$B$12,K5<Rubric!$B$12),Rubric!$B$13,0),2) -> 7.25 | N5: 2 | O5: Baseline draft with illustrative numbers.
A6: Amazon (Twitch) | B6: Software Engineer I (Seattle) | C6: 2 | D6: 3 | E6: Built a CI/CD pipeline with automated integration tests, moving releases from bi-weekly to on-demand and cutting rollbacks from 12% to 3%. | F6: 8 | G6: 8 | H6: 8 | I6: 4 | J6: 7 | K6: 8 | L6: 7 | M6: =ROUND(F6*Rubric!$B$4+G6*Rubric!$B$5+H6*Rubric!$B$6+I6*Rubric!$B$7+J6*Rubric!$B$8+K6*Rubric!$B$9+L6*Rubric!$B$10-IF(OR(H6<Rubric!$B$12,K6<Rubric!$B$12),Rubric!$B$13,0),2) -> 7.35 | N6: 2 | O6: Dull verb; rollback stat buried.
A7: Amazon (Twitch) | B7: Software Engineer I (Seattle) | C7: 3 | D7: 3 | E7: Built CI/CD with automated integration tests, moving releases from bi-weekly to on-demand and cutting rollbacks from 12% to 3%. | F7: 9 | G7: 8 | H7: 8 | I7: 4 | J7: 7 | K7: 8 | L7: 7 | M7: =ROUND(F7*Rubric!$B$4+G7*Rubric!$B$5+H7*Rubric!$B$6+I7*Rubric!$B$7+J7*Rubric!$B$8+K7*Rubric!$B$9+L7*Rubric!$B$10-IF(OR(H7<Rubric!$B$12,K7<Rubric!$B$12),Rubric!$B$13,0),2) -> 7.45 | N7: 2 | O7: Tighten.
A8: Amazon (Twitch) | B8: Software Engineer I (Seattle) | C8: 0 | D8: 4 | E8: Served on on-call rotation; built Grafana/Splunk dashboards and runbooks that cut mean-time-to-detect from 25 to 6 minutes. | F8: 8 | G8: 7 | H8: 8 | I8: 3 | J8: 7 | K8: 8 | L8: 6 | M8: =ROUND(F8*Rubric!$B$4+G8*Rubric!$B$5+H8*Rubric!$B$6+I8*Rubric!$B$7+J8*Rubric!$B$8+K8*Rubric!$B$9+L8*Rubric!$B$10-IF(OR(H8<Rubric!$B$12,K8<Rubric!$B$12),Rubric!$B$13,0),2) -> 6.95 | N8: 3 | O8: Baseline draft with illustrative numbers.
A9: Amazon (Twitch) | B9: Software Engineer I (Seattle) | C9: 2 | D9: 4 | E9: On-call for 4 services: built Grafana/Splunk alerts and runbooks that cut mean-time-to-detect from 25 to 6 minutes and halved repeat pages. | F9: 8 | G9: 8 | H9: 8 | I9: 3 | J9: 7 | K9: 8 | L9: 7 | M9: =ROUND(F9*Rubric!$B$4+G9*Rubric!$B$5+H9*Rubric!$B$6+I9*Rubric!$B$7+J9*Rubric!$B$8+K9*Rubric!$B$9+L9*Rubric!$B$10-IF(OR(H9<Rubric!$B$12,K9<Rubric!$B$12),Rubric!$B$13,0),2) -> 7.25 | N9: 3 | O9: Tool list, not outcome.
A10: Amazon (Twitch) | B10: Software Engineer I (Seattle) | C10: 3 | D10: 4 | E10: On-call for 4 services; Grafana/Splunk alerts and runbooks cut mean-time-to-detect from 25 to 6 minutes and halved repeat pages. | F10: 9 | G10: 8 | H10: 8 | I10: 3 | J10: 7 | K10: 8 | L10: 7 | M10: =ROUND(F10*Rubric!$B$4+G10*Rubric!$B$5+H10*Rubric!$B$6+I10*Rubric!$B$7+J10*Rubric!$B$8+K10*Rubric!$B$9+L10*Rubric!$B$10-IF(OR(H10<Rubric!$B$12,K10<Rubric!$B$12),Rubric!$B$13,0),2) -> 7.35 | N10: 3 | O10: Tighten.
A11: Amazon (Twitch) | B11: Software Engineer I (Seattle) | C11: 0 | D11: 5 | E11: Used GitHub Copilot and Claude Code for test generation, lifting unit-test coverage on owned services from 52% to 81% in 3 weeks. | F11: 8 | G11: 7 | H11: 8 | I11: 8 | J11: 7 | K11: 7 | L11: 7 | M11: =ROUND(F11*Rubric!$B$4+G11*Rubric!$B$5+H11*Rubric!$B$6+I11*Rubric!$B$7+J11*Rubric!$B$8+K11*Rubric!$B$9+L11*Rubric!$B$10-IF(OR(H11<Rubric!$B$12,K11<Rubric!$B$12),Rubric!$B$13,0),2) -> 7.4 | N11: 4 | O11: Baseline draft with illustrative numbers.
A12: Amazon (Twitch) | B12: Software Engineer I (Seattle) | C12: 3 | D12: 5 | E12: Lifted unit-test coverage on owned services from 52% to 81% in 3 weeks, using Copilot/Claude Code to draft tests I reviewed by hand. | F12: 9 | G12: 7 | H12: 8 | I12: 8 | J12: 7 | K12: 8 | L12: 7 | M12: =ROUND(F12*Rubric!$B$4+G12*Rubric!$B$5+H12*Rubric!$B$6+I12*Rubric!$B$7+J12*Rubric!$B$8+K12*Rubric!$B$9+L12*Rubric!$B$10-IF(OR(H12<Rubric!$B$12,K12<Rubric!$B$12),Rubric!$B$13,0),2) -> 7.65 | N12: 4 | O12: Lead with the outcome; human-review caveat adds credibility.
A13: Amazon | B13: Software Engineer I, Payments | C13: 0 | D13: 1 | E13: Shipped 6 features in JPMC's payment-processing stack handling $1.2B/day with zero Sev-1 incidents after launch. | F13: 8 | G13: 8 | H13: 6 | I13: 3 | J13: 9 | K13: 6 | L13: 6 | M13: =ROUND(F13*Rubric!$B$4+G13*Rubric!$B$5+H13*Rubric!$B$6+I13*Rubric!$B$7+J13*Rubric!$B$8+K13*Rubric!$B$9+L13*Rubric!$B$10-IF(OR(H13<Rubric!$B$12,K13<Rubric!$B$12),Rubric!$B$13,0),2) -> 5.75 | N13: 10 | O13: Baseline draft with illustrative numbers.
... A146: Zip | B146: Software Engineer, New Grad (2027 Start) | C146: 0 | D146: 5 | E146: Prototyped an LLM agent to extract and classify requests, hitting 87% accuracy vs. manual baseline. | F146: 8 | G146: 8 | H146: 7 | I146: 9 | J146: 8 | K146: 8 | L146: 9 | M146: =ROUND(F146*Rubric!$B$4+G146*Rubric!$B$5+H146*Rubric!$B$6+I146*Rubric!$B$7+J146*Rubric!$B$8+K146*Rubric!$B$9+L146*Rubric!$B$10-IF(OR(H146<Rubric!$B$12,K146<Rubric!$B$12),Rubric!$B$13,0),2) -> 8 | N146: 134 | O146: Baseline draft with illustrative numbers.

Sheet Round State
A1: Key | B1: After R0 | C1: After R1 | D1: After R2 | E1: After R3
A2: 0 | B2: =SUMIFS('Revision Log'!$M$2:$M$146,'Revision Log'!$N$2:$N$146,$A2,'Revision Log'!$C$2:$C$146,0) -> 7.2 | C2: =SUMIFS('Revision Log'!$M$2:$M$146,'Revision Log'!$N$2:$N$146,$A2,'Revision Log'!$C$2:$C$146,0) -> 7.2 | D2: =SUMIFS('Revision Log'!$M$2:$M$146,'Revision Log'!$N$2:$N$146,$A2,'Revision Log'!$C$2:$C$146,2) -> 7.5 | E2: =SUMIFS('Revision Log'!$M$2:$M$146,'Revision Log'!$N$2:$N$146,$A2,'Revision Log'!$C$2:$C$146,2) -> 7.5
A3: 1 | B3: =SUMIFS('Revision Log'!$M$2:$M$146,'Revision Log'!$N$2:$N$146,$A3,'Revision Log'!$C$2:$C$146,0) -> 8.05 | C3: =SUMIFS('Revision Log'!$M$2:$M$146,'Revision Log'!$N$2:$N$146,$A3,'Revision Log'!$C$2:$C$146,0) -> 8.05 | D3: =SUMIFS('Revision Log'!$M$2:$M$146,'Revision Log'!$N$2:$N$146,$A3,'Revision Log'!$C$2:$C$146,0) -> 8.05 | E3: =SUMIFS('Revision Log'!$M$2:$M$146,'Revision Log'!$N$2:$N$146,$A3,'Revision Log'!$C$2:$C$146,0) -> 8.05
A4: 2 | B4: =SUMIFS('Revision Log'!$M$2:$M$146,'Revision Log'!$N$2:$N$146,$A4,'Revision Log'!$C$2:$C$146,0) -> 7.25 | C4: =SUMIFS('Revision Log'!$M$2:$M$146,'Revision Log'!$N$2:$N$146,$A4,'Revision Log'!$C$2:$C$146,0) -> 7.25 | D4: =SUMIFS('Revision Log'!$M$2:$M$146,'Revision Log'!$N$2:$N$146,$A4,'Revision Log'!$C$2:$C$146,2) -> 7.35 | E4: =SUMIFS('Revision Log'!$M$2:$M$146,'Revision Log'!$N$2:$N$146,$A4,'Revision Log'!$C$2:$C$146,3) -> 7.45
A5: 3 | B5: =SUMIFS('Revision Log'!$M$2:$M$146,'Revision Log'!$N$2:$N$146,$A5,'Revision Log'!$C$2:$C$146,0) -> 6.95 | C5: =SUMIFS('Revision Log'!$M$2:$M$146,'Revision Log'!$N$2:$N$146,$A5,'Revision Log'!$C$2:$C$146,0) -> 6.95 | D5: =SUMIFS('Revision Log'!$M$2:$M$146,'Revision Log'!$N$2:$N$146,$A5,'Revision Log'!$C$2:$C$146,2) -> 7.25 | E5: =SUMIFS('Revision Log'!$M$2:$M$146,'Revision Log'!$N$2:$N$146,$A5,'Revision Log'!$C$2:$C$146,3) -> 7.35
A6: 4 | B6: =SUMIFS('Revision Log'!$M$2:$M$146,'Revision Log'!$N$2:$N$146,$A6,'Revision Log'!$C$2:$C$146,0) -> 7.4 | C6: =SUMIFS('Revision Log'!$M$2:$M$146,'Revision Log'!$N$2:$N$146,$A6,'Revision Log'!$C$2:$C$146,0) -> 7.4 | D6: =SUMIFS('Revision Log'!$M$2:$M$146,'Revision Log'!$N$2:$N$146,$A6,'Revision Log'!$C$2:$C$146,0) -> 7.4 | E6: =SUMIFS('Revision Log'!$M$2:$M$146,'Revision Log'!$N$2:$N$146,$A6,'Revision Log'!$C$2:$C$146,3) -> 7.65
A7: 10 | B7: =SUMIFS('Revision Log'!$M$2:$M$146,'Revision Log'!$N$2:$N$146,$A7,'Revision Log'!$C$2:$C$146,0) -> 5.75 | C7: =SUMIFS('Revision Log'!$M$2:$M$146,'Revision Log'!$N$2:$N$146,$A7,'Revision Log'!$C$2:$C$146,1) -> 7 | D7: =SUMIFS('Revision Log'!$M$2:$M$146,'Revision Log'!$N$2:$N$146,$A7,'Revision Log'!$C$2:$C$146,2) -> 7.35 | E7: =SUMIFS('Revision Log'!$M$2:$M$146,'Revision Log'!$N$2:$N$146,$A7,'Revision Log'!$C$2:$C$146,2) -> 7.35
A8: 11 | B8: =SUMIFS('Revision Log'!$M$2:$M$146,'Revision Log'!$N$2:$N$146,$A8,'Revision Log'!$C$2:$C$146,0) -> 8.2 | C8: =SUMIFS('Revision Log'!$M$2:$M$146,'Revision Log'!$N$2:$N$146,$A8,'Revision Log'!$C$2:$C$146,0) -> 8.2 | D8: =SUMIFS('Revision Log'!$M$2:$M$146,'Revision Log'!$N$2:$N$146,$A8,'Revision Log'!$C$2:$C$146,0) -> 8.2 | E8: =SUMIFS('Revision Log'!$M$2:$M$146,'Revision Log'!$N$2:$N$146,$A8,'Revision Log'!$C$2:$C$146,0) -> 8.2
A9: 12 | B9: =SUMIFS('Revision Log'!$M$2:$M$146,'Revision Log'!$N$2:$N$146,$A9,'Revision Log'!$C$2:$C$146,0) -> 7.85 | C9: =SUMIFS('Revision Log'!$M$2:$M$146,'Revision Log'!$N$2:$N$146,$A9,'Revision Log'!$C$2:$C$146,0) -> 7.85 | D9: =SUMIFS('Revision Log'!$M$2:$M$146,'Revision Log'!$N$2:$N$146,$A9,'Revision Log'!$C$2:$C$146,0) -> 7.85 | E9: =SUMIFS('Revision Log'!$M$2:$M$146,'Revision Log'!$N$2:$N$146,$A9,'Revision Log'!$C$2:$C$146,0) -> 7.85
A10: 13 | B10: =SUMIFS('Revision Log'!$M$2:$M$146,'Revision Log'!$N$2:$N$146,$A10,'Revision Log'!$C$2:$C$146,0) -> 7.5 | C10: =SUMIFS('Revision Log'!$M$2:$M$146,'Revision Log'!$N$2:$N$146,$A10,'Revision Log'!$C$2:$C$146,0) -> 7.5 | D10: =SUMIFS('Revision Log'!$M$2:$M$146,'Revision Log'!$N$2:$N$146,$A10,'Revision Log'!$C$2:$C$146,0) -> 7.5 | E10: =SUMIFS('Revision Log'!$M$2:$M$146,'Revision Log'!$N$2:$N$146,$A10,'Revision Log'!$C$2:$C$146,3) -> 7.6
A11: 14 | B11: =SUMIFS('Revision Log'!$M$2:$M$146,'Revision Log'!$N$2:$N$146,$A11,'Revision Log'!$C$2:$C$146,0) -> 7.85 | C11: =SUMIFS('Revision Log'!$M$2:$M$146,'Revision Log'!$N$2:$N$146,$A11,'Revision Log'!$C$2:$C$146,0) -> 7.85 | D11: =SUMIFS('Revision Log'!$M$2:$M$146,'Revision Log'!$N$2:$N$146,$A11,'Revision Log'!$C$2:$C$146,0) -> 7.85 | E11: =SUMIFS('Revision Log'!$M$2:$M$146,'Revision Log'!$N$2:$N$146,$A11,'Revision Log'!$C$2:$C$146,0) -> 7.85
A12: 20 | B12: =SUMIFS('Revision Log'!$M$2:$M$146,'Revision Log'!$N$2:$N$146,$A12,'Revision Log'!$C$2:$C$146,0) -> 7.05 | C12: =SUMIFS('Revision Log'!$M$2:$M$146,'Revision Log'!$N$2:$N$146,$A12,'Revision Log'!$C$2:$C$146,0) -> 7.05 | D12: =SUMIFS('Revision Log'!$M$2:$M$146,'Revision Log'!$N$2:$N$146,$A12,'Revision Log'!$C$2:$C$146,2) -> 7.35 | E12: =SUMIFS('Revision Log'!$M$2:$M$146,'Revision Log'!$N$2:$N$146,$A12,'Revision Log'!$C$2:$C$146,2) -> 7.35
A13: 21 | B13: =SUMIFS('Revision Log'!$M$2:$M$146,'Revision Log'!$N$2:$N$146,$A13,'Revision Log'!$C$2:$C$146,0) -> 6.95 | C13: =SUMIFS('Revision Log'!$M$2:$M$146,'Revision Log'!$N$2:$N$146,$A13,'Revision Log'!$C$2:$C$146,0) -> 6.95 | D13: =SUMIFS('Revision Log'!$M$2:$M$146,'Revision Log'!$N$2:$N$146,$A13,'Revision Log'!$C$2:$C$146,2) -> 7.4 | E13: =SUMIFS('Revision Log'!$M$2:$M$146,'Revision Log'!$N$2:$N$146,$A13,'Revision Log'!$C$2:$C$146,2) -> 7.4
A14: 22 | B14: =SUMIFS('Revision Log'!$M$2:$M$146,'Revision Log'!$N$2:$N$146,$A14,'Revision Log'!$C$2:$C$146,0) -> 6.85 | C14: =SUMIFS('Revision Log'!$M$2:$M$146,'Revision Log'!$N$2:$N$146,$A14,'Revision Log'!$C$2:$C$146,1) -> 7.1 | D14: =SUMIFS('Revision Log'!$M$2:$M$146,'Revision Log'!$N$2:$N$146,$A14,'Revision Log'!$C$2:$C$146,2) -> 7.4 | E14: =SUMIFS('Revision Log'!$M$2:$M$146,'Revision Log'!$N$2:$N$146,$A14,'Revision Log'!$C$2:$C$146,2) -> 7.4
A15: 23 | B15: =SUMIFS('Revision Log'!$M$2:$M$146,'Revision Log'!$N$2:$N$146,$A15,'Revision Log'!$C$2:$C$146,0) -> 6.1 | C15: =SUMIFS('Revision Log'!$M$2:$M$146,'Revision Log'!$N$2:$N$146,$A15,'Revision Log'!$C$2:$C$146,1) -> 6.6 | D15: =SUMIFS('Revision Log'!$M$2:$M$146,'Revision Log'!$N$2:$N$146,$A15,'Revision Log'!$C$2:$C$146,2) -> 6.8 | E15: =SUMIFS('Revision Log'!$M$2:$M$146,'Revision Log'!$N$2:$N$146,$A15,'Revision Log'!$C$2:$C$146,3) -> 7.35
